Workbook

Sheet fr
A1: Rota | B1: Toplam Mesafe (km) | D1: maliyet | H1: Ziyaret edilen depo sayısı | I1: kapasite | J1: hacim | K1: 100km tam yüklü yakıt | N1: 530mm | O1: 365mm | P1: 315mm
A2: Rota 1 | B2: 112.83635 | C2: 371.87675 | D2: 43.667667 | H2: 3 | I2: 750 | J2: 45.702562 | K2: 25 | L2: Kamyon (47m3) | M2: Bir kasanın hacmi | N2: 0.06093675 | O2: m3
A3: Rota 2 | B3: 102.37785 | C3: 365.21469 | D3: 39.620229 | H3: 4 | I3: 900 | J3: 54.843075 | K3: 30 | L3: Kırkayak (55m3)
A4: Rota 3 | B4: 190.60286 | C4: 421.41402 | D4: 73.763307 | H4: 5 | I4: 1200 | J4: 73.1241 | K4: 38 | L4: Optima Tenteli (88m3)
A5: Rota 4 | B5: 100.05667 | C5: 257.28245 | D5: 32.268277 | H5: 6 | I5: 1400 | J5: 85.31145 | K5: 38 | L5: Optima Tenteli (88m3)
A6: Rota 5 | B6: 243.66005 | C6: 339.49538 | D6: 78.580366 | H6: fuel_consumption_per_100km = 12 # litre/100 km (tam yüklü araç)
A7: Rota 6 | B7: 162.78126 | C7: 570.49069 | D7: 79.795376 | H7: fuel_price_per_litre = 1.29 # Euro/litre
A8: Rota 7 | B8: 197.58471 | C8: 596.2522 | D8: 96.856025 | H8: fuel_consumption = distance * (fuel_consumption_per_100km / 100) # Tüketim (litre)
A9: Rota 8 | B9: 131.82355 | C9: 383.9716 | D9: 51.015713 | H9: cost = fuel_consumption * fuel_price_per_litre # Yakıt maliyeti (TL)
A10: Rota 9 | B10: 187.337 | C10: 588.66685 | D10: 91.832599
A11: Rota 10 | B11: 177.3995 | C11: 413.00348 | D11: 68.653605
A12: Rota 11 | B12: 242.63716 | C12: 779.60002 | D12: 118.94073
A13: Rota 12 | B13: 154.44857 | C13: 564.32283 | D13: 75.710691
A14: Rota 13 | B14: 177.61822 | C14: 581.47301 | D14: 87.068451
A15: Rota 14 | B15: 229.77442 | C15: 620.07903 | D15: 112.63542
A16: Rota 15 | B16: 119.902 | C16: 538.75146 | D16: 58.77596
A17: Rota 16 | B17: 140.63465 | C17: 554.09777 | D17: 68.939104
A18: Rota 17 | B18: 266.44218 | C18: 647.2205 | D18: 130.60996
A19: Rota 18 | B19: 267.68654 | C19: 798.14157 | D19: 131.21994
A20: Rota 19 | B20: 132.93075 | C20: 548.39534 | D20: 65.162654
A21: Rota 20 | B21: 157.3986 | C21: 716.50644 | D21: 77.156794
... A31: Rota 30 | B31: 104.42105 | C31: 259.78105 | D31: 33.675788

Sheet Beta
A1: Ad | B1: Tedarikçi 1 (K=1) | C1: Tedarikçi 7 (K=2) | D1: Tedarikçi 10 (K=3) | E1: Tedarikçi 16 (K=4) | F1: Tedarikçi 18 (K=5) | G1: Tedarikçi 23 (K=6) | H1: Tedarikçi 25 (K=7) | I1: Tedarikçi 27 (K=8) | J1: Tedarikçi 33 (K=9) | K1: Tedarikçi 38 (K=10) | L1: Tedarikçi 39 (K=11) | M1: Tedarikçi 40 (K=12) | N1: Tedarikçi 42 (K=13) | O1: Tedarikçi 47 (K=14) | P1: Tedarikçi 55 (K=15) | Q1: Tedarikçi 62 (K=16) | R1: Tedarikçi 70 (K=17) | S1: Tedarikçi 71 (K=18) | T1: Tedarikçi 73 (K=19) | U1: Tedarikçi 75 (K=20) | V1: Tedarikçi 78 (K=21) | W1: Tedarikçi 85 (K=22) | X1: Tedarikçi 89 (K=23) | Y1: Tedarikçi 97 (K=24) | Z1: Tedarikçi 100 (K=25) | AA1: Tedarikçi 101 (K=26) | AB1: Tedarikçi 102 (K=27) | AD1: Tedarikçi 101 (K=26) | AE1: Tedarikçi 102 (K=27) | AG1: ortak araç kullanımının kaldırıldığı ve kooperatifin araç koyduğu senaryo için mesafeye bağlı maliyelere 80 euro eklenmiştir bu da kooperatifin o aracın bakımı için katlandığı bir maliyettir
A2: Tedarikçi 1 (K=1) | B2: 5 | C2: 52.197388 | D2: 51.513115 | E2: 51.97627 | F2: 50.570737 | G2: 51.167222 | H2: 52.153783 | I2: 51.327167 | J2: 51.659268 | K2: 51.4238 | L2: 52.082867 | M2: 51.29752 | N2: 61.776955 | O2: 60.991588 | P2: 59.501559 | Q2: 61.661788 | R2: 59.650878 | S2: 60.140936 | T2: 59.332892 | U2: 58.412956 | V2: 57.887659 | W2: 60.01241 | X2: 58.653367 | Y2: 59.712825 | Z2: 60.249062 | AA2: 89.97012 | AB2: 80.76103 | AD2: 9.9701198 | AE2: 0.7610304 | AG2: =AD2+80 -> 89.97012 | AH2: =AE2+80 -> 80.76103
A3: Tedarikçi 2 | B3: 50.551682 | C3: 51.649213 | D3: 51.067548 | E3: 51.457736 | F3: 50.379749 | G3: 50.646861 | H3: 51.608162 | I3: 51.053385 | J3: 51.174671 | K3: 50.873645 | L3: 51.531257 | M3: 50.87463 | N3: 62.105984 | O3: 61.351606 | P3: 59.883972 | Q3: 62.110801 | R3: 59.939849 | S3: 60.473938 | T3: 59.690798 | U3: 58.756839 | V3: 58.266725 | W3: 60.461201 | X3: 58.918557 | Y3: 60.035103 | Z3: 60.667867 | AA3: 90.351951 | AB3: 80.225871 | AD3: 10.351951 | AE3: 0.22587072 | AG3: =AD3+80 -> 90.351951 | AH3: =AE3+80 -> 80.225871
A4: Tedarikçi 3 | B4: 51.368717 | C4: 50.998307 | D4: 51.303251 | E4: 50.640281 | F4: 50.832545 | G4: 50.853439 | H4: 50.93055 | I4: 51.609697 | J4: 50.290814 | K4: 50.663667 | L4: 51.018944 | M4: 50.183111 | N4: 62.976118 | O4: 62.233892 | P4: 60.772791 | Q4: 63.002661 | R4: 60.791622 | S4: 61.346558 | T4: 60.572989 | U4: 59.634699 | V4: 59.155246 | W4: 61.352999 | X4: 59.757945 | Y4: 60.903359 | Z4: 61.561523 | AA4: 91.240535 | AB4: 80.823188 | AD4: 11.240535 | AE4: 0.82318848 | AG4: =AD4+80 -> 91.240535 | AH4: =AE4+80 -> 80.823188
A5: Tedarikçi 4 | B5: 51.022398 | C5: 51.17551 | D5: 50.918134 | E5: 50.986095 | F5: 50.622537 | G5: 50.426614 | H5: 51.131433 | I5: 51.13835 | J5: 50.740355 | K5: 50.455818 | L5: 51.078527 | M5: 50.559051 | N5: 62.490148 | O5: 61.755313 | P5: 60.301784 | Q5: 62.5628 | R5: 60.300399 | S5: 60.861889 | T5: 60.094551 | U5: 59.153223 | V5: 58.684101 | W5: 60.913586 | X5: 59.264961 | Y5: 60.416811 | Z5: 61.105143 | AA5: 90.769095 | AB5: 80.342708 | AD5: 10.769095 | AE5: 0.34270787 | AG5: =AD5+80 -> 90.769095 | AH5: =AE5+80 -> 80.342708
A6: Tedarikçi 5 | B6: 51.882743 | C6: 50.461522 | D6: 50.831516 | E6: 50.707588 | F6: 51.519793 | G6: 50.763484 | H6: 50.479225 | I6: 51.338523 | J6: 50.870137 | K6: 50.459251 | L6: 50.227594 | M6: 51.112858 | N6: 62.864269 | O6: 62.187251 | P6: 60.780898 | Q6: 63.155547 | R6: 60.619419 | S6: 61.251744 | T6: 60.532217 | U6: 59.573885 | V6: 59.168454 | W6: 61.511139 | X6: 59.553506 | Y6: 60.791238 | Z6: 61.645725 | AA6: 91.244591 | AB6: 81.1242 | AD6: 11.244591 | AE6: 1.1241995 | AG6: =AD6+80 -> 91.244591 | AH6: =AE6+80 -> 81.1242
A7: Tedarikçi 6 | B7: 51.671169 | C7: 50.908134 | D7: 51.532674 | E7: 50.459332 | F7: 51.118113 | G7: 51.122741 | H7: 50.830685 | I7: 51.887882 | J7: 50.124544 | K7: 50.865795 | L7: 51.011001 | M7: 50.384088 | N7: 63.292418 | O7: 62.552055 | P7: 61.091412 | Q7: 63.317132 | R7: 61.104393 | S7: 61.663338 | T7: 60.891159 | U7: 59.952338 | V7: 59.473866 | W7: 61.667452 | X7: 60.068132 | Y7: 61.219393 | Z7: 61.879043 | AA7: 91.559155 | AB7: 81.139209 | AD7: 11.559155 | AE7: 1.1392093 | AG7: =AD7+80 -> 91.559155 | AH7: =AE7+80 -> 81.139209
A8: Tedarikçi 7 (K=2) | B8: 52.197388 | C8: 5 | D8: 51.293031 | E8: 50.470187 | F8: 51.752877 | G8: 51.168509 | H8: 50.079192 | I8: 51.797381 | J8: 50.804103 | K8: 50.821182 | L8: 50.26439 | M8: 51.172673 | N8: 63.325754 | O8: 62.647149 | P8: 61.23749 | Q8: 63.597482 | R8: 61.080482 | S8: 61.712969 | T8: 60.991626 | U8: 60.033978 | V8: 59.624188 | W8: 61.951747 | X8: 60.013738 | Y8: 61.252676 | Z8: 62.095763 | AA8: 91.701572 | AB8: 81.466341 | AD8: 11.701572 | AE8: 1.4663409 | AG8: =AD8+80 -> 91.701572 | AH8: =AE8+80 -> 81.466341
A9: Tedarikçi 8 | B9: 51.844967 | C9: 50.435361 | D9: 50.867018 | E9: 50.634398 | F9: 51.464501 | G9: 50.749844 | H9: 50.440046 | I9: 51.363915 | J9: 50.78797 | K9: 50.423759 | L9: 50.239855 | M9: 51.035622 | N9: 62.896249 | O9: 62.213679 | P9: 60.802343 | Q9: 63.165013 | R9: 60.65581 | S9: 61.281961 | T9: 60.557725 | U9: 59.600762 | V9: 59.188913 | W9: 61.519767 | X9: 59.592183 | Y9: 60.822763 | Z9: 61.660865 | AA9: 91.266511 | AB9: 81.090595 | AD9: 11.266511 | AE9: 1.090595 | AG9: =AD9+80 -> 91.266511 | AH9: =AE9+80 -> 81.090595
A10: Tedarikçi 9 | B10: 51.889975 | C10: 50.348787 | D10: 50.963067 | E10: 50.546853 | F10: 51.486734 | G10: 50.822582 | H10: 50.346316 | I10: 51.456766 | J10: 50.732385 | K10: 50.482145 | L10: 50.202203 | M10: 51.011812 | N10: 62.990434 | O10: 62.30589 | P10: 60.892448 | Q10: 63.248695 | R10: 60.751265 | S10: 61.375578 | T10: 60.64959 | U10: 59.693184 | V10: 59.278594 | W10: 61.602974 | X10: 59.688175 | Y10: 60.91682 | Z10: 61.747815 | AA10: 91.356823 | AB10: 81.142742 | AD10: 11.356823 | AE10: 1.1427422 | AG10: =AD10+80 -> 91.356823 | AH10: =AE10+80 -> 81.142742
A11: Tedarikçi 10 (K=3) | B11: 51.513115 | C11: 51.293031 | D11: 5 | E11: 51.440185 | F11: 51.412155 | G11: 50.492946 | H11: 51.30628 | I11: 50.521942 | J11: 51.422013 | K11: 50.668427 | L11: 51.046593 | M11: 51.433271 | N11: 62.032768 | O11: 61.358476 | P11: 59.958484 | Q11: 62.36112 | R11: 59.789154 | S11: 60.420618 | T11: 59.704413 | U11: 58.744828 | V11: 58.347948 | W11: 60.71985 | X11: 58.725172 | Y11: 59.959791 | Z11: 60.83593 | AA11: 90.421382 | AB11: 80.855618 | AD11: 10.421382 | AE11: 0.85561771 | AG11: =AD11+80 -> 90.421382 | AH11: =AE11+80 -> 80.855618
A12: Tedarikçi 11 | B12: 51.511006 | C12: 50.691214 | D12: 50.844996 | E12: 50.627459 | F12: 51.105417 | G12: 50.526413 | H12: 50.656917 | I12: 51.260984 | J12: 50.584486 | K12: 50.184799 | L12: 50.58396 | M12: 50.717011 | N12: 62.773841 | O12: 62.067247 | P12: 60.635877 | Q12: 62.951671 | R12: 60.554919 | S12: 61.152463 | T12: 60.408257 | U12: 59.457772 | V12: 59.019497 | W12: 61.304014 | X12: 59.502991 | Y12: 60.699365 | Z12: 61.469122 | AA12: 91.101727 | AB12: 80.775386 | AD12: 11.101727 | AE12: 0.77538602 | AG12: =AD12+80 -> 91.101727 | AH12: =AE12+80 -> 80.775386
A13: Tedarikçi 12 | B13: 51.143482 | C13: 51.279385 | D13: 51.394349 | E13: 50.920886 | F13: 50.582302 | G13: 50.908355 | H13: 51.213157 | I13: 51.615258 | J13: 50.554275 | K13: 50.824662 | L13: 51.28202 | M13: 50.154799 | N13: 62.841492 | O13: 62.082596 | P13: 60.609007 | Q13: 62.802402 | R13: 60.676134 | S13: 61.208965 | T13: 60.421995 | U13: 59.490311 | V13: 58.992422 | W13: 61.152838 | X13: 59.653243 | Y13: 60.770996 | Z13: 61.378257 | AA13: 91.077244 | AB13: 80.738065 | AD13: 11.077244 | AE13: 0.73806497 | AG13: =AD13+80 -> 91.077244 | AH13: =AE13+80 -> 80.738065
... A101: Tedarikçi 100 (K=25) | B101: 60.249062 | C101: 62.095763 | D101: 60.83593 | E101: 62.074243 | F101: 60.819436 | G101: 60.947166 | H101: 62.089948 | I101: 60.315252 | J101: 61.838179 | K101: 61.301691 | L101: 61.870657 | M101: 61.528083 | N101: 52.895047 | O101: 51.779574 | P101: 51.233569 | Q101: 51.737587 | R101: 53.200915 | S101: 52.222073 | T101: 51.820128 | U101: 52.589929 | V101: 52.567857 | W101: 50.938099 | X101: 53.822364 | Y101: 52.48351 | Z101: 5 | AA101: 81.048292 | AB101: 90.762638 | AD101: 1.0482918 | AE101: 10.762638 | AG101: =AD101+80 -> 81.048292 | AH101: =AE101+80 -> 90.762638

Sheet vehicleassign
A1: Ad | B1: Tedarikçi 1 (K=1) | C1: Tedarikçi 7 (K=2) | D1: Tedarikçi 10 (K=3) | E1: Tedarikçi 16 (K=4) | F1: Tedarikçi 18 (K=5) | G1: Tedarikçi 23 (K=6) | H1: Tedarikçi 25 (K=7) | I1: Tedarikçi 27 (K=8) | J1: Tedarikçi 33 (K=9) | K1: Tedarikçi 38 (K=10) | L1: Tedarikçi 39 (K=11) | M1: Tedarikçi 40 (K=12) | N1: Tedarikçi 42 (K=13) | O1: Tedarikçi 47 (K=14) | P1: Tedarikçi 55 (K=15) | Q1: Tedarikçi 62 (K=16) | R1: Tedarikçi 70 (K=17) | S1: Tedarikçi 71 (K=18) | T1: Tedarikçi 73 (K=19) | U1: Tedarikçi 75 (K=20) | V1: Tedarikçi 78 (K=21) | W1: Tedarikçi 85 (K=22) | X1: Tedarikçi 89 (K=23) | Y1: Tedarikçi 97 (K=24) | Z1: Tedarikçi 100 (K=25) | AA1: Tedarikçi 101 (K=26-izmir) | AB1: Tedarikçi 102 (K=27-aydın)
A2: Tedarikçi 1 (K=1) | B2: 1 | C2: 0 | D2: 0 | E2: 0 | F2: 0 | G2: 0 | H2: 0 | I2: 0 | J2: 0 | K2: 0 | L2: 0 | M2: 0 | N2: 0 | O2: 0 | P2: 0 | Q2: 0 | R2: 0 | S2: 0 | T2: 0 | U2: 0 | V2: 0 | W2: 0 | X2: 0 | Y2: 0 | Z2: 0 | AA2: 0 | AB2: 0
A3: Tedarikçi 2 | B3: 0 | C3: 0 | D3: 0 | E3: 0 | F3: 0 | G3: 0 | H3: 0 | I3: 0 | J3: 0 | K3: 0 | L3: 0 | M3: 0 | N3: 0 | O3: 0 | P3: 0 | Q3: 0 | R3: 0 | S3: 0 | T3: 0 | U3: 0 | V3: 0 | W3: 0 | X3: 0 | Y3: 0 | Z3: 0 | AA3: 0 | AB3: 1
A4: Tedarikçi 3 | B4: 0 | C4: 0 | D4: 0 | E4: 0 | F4: 0 | G4: 0 | H4: 0 | I4: 0 | J4: 0 | K4: 0 | L4: 0 | M4: 0 | N4: 0 | O4: 0 | P4: 0 | Q4: 0 | R4: 0 | S4: 0 | T4: 0 | U4: 0 | V4: 0 | W4: 0 | X4: 0 | Y4: 0 | Z4: 0 | AA4: 0 | AB4: 1
A5: Tedarikçi 4 | B5: 0 | C5: 0 | D5: 0 | E5: 0 | F5: 0 | G5: 0 | H5: 0 | I5: 0 | J5: 0 | K5: 0 | L5: 0 | M5: 0 | N5: 0 | O5: 0 | P5: 0 | Q5: 0 | R5: 0 | S5: 0 | T5: 0 | U5: 0 | V5: 0 | W5: 0 | X5: 0 | Y5: 0 | Z5: 0 | AA5: 0 | AB5: 1
A6: Tedarikçi 5 | B6: 0 | C6: 0 | D6: 0 | E6: 0 | F6: 0 | G6: 0 | H6: 0 | I6: 0 | J6: 0 | K6: 0 | L6: 0 | M6: 0 | N6: 0 | O6: 0 | P6: 0 | Q6: 0 | R6: 0 | S6: 0 | T6: 0 | U6: 0 | V6: 0 | W6: 0 | X6: 0 | Y6: 0 | Z6: 0 | AA6: 0 | AB6: 1
A7: Tedarikçi 6 | B7: 0 | C7: 0 | D7: 0 | E7: 0 | F7: 0 | G7: 0 | H7: 0 | I7: 0 | J7: 0 | K7: 0 | L7: 0 | M7: 0 | N7: 0 | O7: 0 | P7: 0 | Q7: 0 | R7: 0 | S7: 0 | T7: 0 | U7: 0 | V7: 0 | W7: 0 | X7: 0 | Y7: 0 | Z7: 0 | AA7: 0 | AB7: 1
A8: Tedarikçi 7 (K=2) | B8: 0 | C8: 1 | D8: 0 | E8: 0 | F8: 0 | G8: 0 | H8: 0 | I8: 0 | J8: 0 | K8: 0 | L8: 0 | M8: 0 | N8: 0 | O8: 0 | P8: 0 | Q8: 0 | R8: 0 | S8: 0 | T8: 0 | U8: 0 | V8: 0 | W8: 0 | X8: 0 | Y8: 0 | Z8: 0 | AA8: 0 | AB8: 0
A9: Tedarikçi 8 | B9: 0 | C9: 0 | D9: 0 | E9: 0 | F9: 0 | G9: 0 | H9: 0 | I9: 0 | J9: 0 | K9: 0 | L9: 0 | M9: 0 | N9: 0 | O9: 0 | P9: 0 | Q9: 0 | R9: 0 | S9: 0 | T9: 0 | U9: 0 | V9: 0 | W9: 0 | X9: 0 | Y9: 0 | Z9: 0 | AA9: 0 | AB9: 1
A10: Tedarikçi 9 | B10: 0 | C10: 0 | D10: 0 | E10: 0 | F10: 0 | G10: 0 | H10: 0 | I10: 0 | J10: 0 | K10: 0 | L10: 0 | M10: 0 | N10: 0 | O10: 0 | P10: 0 | Q10: 0 | R10: 0 | S10: 0 | T10: 0 | U10: 0 | V10: 0 | W10: 0 | X10: 0 | Y10: 0 | Z10: 0 | AA10: 0 | AB10: 1
A11: Tedarikçi 10 (K=3) | B11: 0 | C11: 0 | D11: 1 | E11: 0 | F11: 0 | G11: 0 | H11: 0 | I11: 0 | J11: 0 | K11: 0 | L11: 0 | M11: 0 | N11: 0 | O11: 0 | P11: 0 | Q11: 0 | R11: 0 | S11: 0 | T11: 0 | U11: 0 | V11: 0 | W11: 0 | X11: 0 | Y11: 0 | Z11: 0 | AA11: 0 | AB11: 0
A12: Tedarikçi 11 | B12: 0 | C12: 0 | D12: 0 | E12: 0 | F12: 0 | G12: 0 | H12: 0 | I12: 0 | J12: 0 | K12: 0 | L12: 0 | M12: 0 | N12: 0 | O12: 0 | P12: 0 | Q12: 0 | R12: 0 | S12: 0 | T12: 0 | U12: 0 | V12: 0 | W12: 0 | X12: 0 | Y12: 0 | Z12: 0 | AA12: 0 | AB12: 1
A13: Tedarikçi 12 | B13: 0 | C13: 0 | D13: 0 | E13: 0 | F13: 0 | G13: 0 | H13: 0 | I13: 0 | J13: 0 | K13: 0 | L13: 0 | M13: 0 | N13: 0 | O13: 0 | P13: 0 | Q13: 0 | R13: 0 | S13: 0 | T13: 0 | U13: 0 | V13: 0 | W13: 0 | X13: 0 | Y13: 0 | Z13: 0 | AA13: 0 | AB13: 1
... A101: Tedarikçi 100 (K=25) | B101: 0 | C101: 0 | D101: 0 | E101: 0 | F101: 0 | G101: 0 | H101: 0 | I101: 0 | J101: 0 | K101: 0 | L101: 0 | M101: 0 | N101: 0 | O101: 0 | P101: 0 | Q101: 0 | R101: 0 | S101: 0 | T101: 0 | U101: 0 | V101: 0 | W101: 0 | X101: 0 | Y101: 0 | Z101: 1 | AA101: 0 | AB101: 0

Sheet nr
A2: 1 | B2: 2 | C2: 25 | D2: 24 | E2: 14 | F2: 13
A3: 2 | B3: 1 | C3: 16 | D3: 17 | E3: 23 | F3: 20
A4: 3 | B4: 1 | C4: 10 | D4: 22 | E4: 27 | F4: 30
A5: 4 | B5: 2 | C5: 28 | D5: 26 | E5: 19
A6: 5 | B6: 3 | C6: 11 | D6: 12 | E6: 29
A7: 6 | B7: 3 | C7: 8 | D7: 18 | E7: 21 | F7: 15 | G7: 9
A8: 7 | B8: 2 | C8: 19 | D8: 20 | E8: 14 | F8: 7 | G8: 2
A9: 8 | B9: 3 | C9: 17 | D9: 15 | E9: 21 | F9: 25
A10: 9 | B10: 2 | C10: 22 | D10: 8 | E10: 6 | F10: 5 | G10: 1
A11: 10 | B11: 1 | C11: 23 | D11: 13 | E11: 10 | F11: 11
A12: 11 | B12: 2 | C12: 29 | D12: 26 | E12: 24 | F12: 16 | G12: 4 | H12: 3
A13: 12 | B13: 3 | C13: 9 | D13: 18 | E13: 30 | F13: 28 | G13: 27
A14: 13 | B14: 2 | C14: 30 | D14: 23 | E14: 5 | F14: 4 | G14: 2
A15: 14 | B15: 1 | C15: 12 | D15: 15 | E15: 21 | F15: 25 | G15: 28
A16: 15 | B16: 3 | C16: 7 | D16: 9 | E16: 10 | F16: 16 | G16: 22
A17: 16 | B17: 2 | C17: 18 | D17: 19 | E17: 17 | F17: 14 | G17: 12
A18: 17 | B18: 2 | C18: 29 | D18: 24 | E18: 8 | F18: 1 | G18: 3
A19: 18 | B19: 2 | C19: 27 | D19: 20 | E19: 7 | F19: 6 | G19: 4 | H19: 2
A20: 19 | B20: 1 | C20: 7 | D20: 6 | E20: 5 | F20: 3 | G20: 1
A21: 20 | B21: 3 | C21: 20 | D21: 21 | E21: 22 | F21: 24 | G21: 26 | H21: 28
A22: 21 | B22: 2 | C22: 23 | D22: 8 | E22: 16 | F22: 13 | G22: 11
A23: 22 | B23: 3 | C23: 6 | D23: 5 | E23: 4 | F23: 3 | G23: 2 | H23: 1
A24: 23 | B24: 3 | C24: 17 | D24: 30 | E24: 14 | F24: 9 | G24: 10 | H24: 12
A25: 24 | B25: 2 | C25: 18 | D25: 19 | E25: 25 | F25: 26 | G25: 27 | H25: 29
A26: 25 | B26: 1 | C26: 11 | D26: 13 | E26: 15 | F26: 20 | G26: 22 | H26: 26
A27: 26 | B27: 1 | C27: 10 | D27: 16 | E27: 15 | F27: 27
A28: 27 | B28: 3 | C28: 7 | D28: 13 | E28: 14 | F28: 17 | G28: 28
A29: 28 | B29: 1 | C29: 9 | D29: 12 | E29: 11
A30: 29 | B30: 1 | C30: 8 | D30: 19 | E30: 23 | F30: 25 | G30: 24 | H30: 21
A31: 30 | B31: 1 | C31: 18 | D31: 30 | E31: 29

Sheet vehicleassign2
A1: Ad | B1: Tedarikçi 1 (K=1) | C1: Tedarikçi 7 (K=2) | D1: Tedarikçi 10 (K=3) | E1: Tedarikçi 16 (K=4) | F1: Tedarikçi 18 (K=5) | G1: Tedarikçi 23 (K=6) | H1: Tedarikçi 25 (K=7) | I1: Tedarikçi 27 (K=8) | J1: Tedarikçi 33 (K=9) | K1: Tedarikçi 38 (K=10) | L1: Tedarikçi 39 (K=11) | M1: Tedarikçi 40 (K=12) | N1: Tedarikçi 42 (K=13) | O1: Tedarikçi 47 (K=14) | P1: Tedarikçi 55 (K=15) | Q1: Tedarikçi 62 (K=16) | R1: Tedarikçi 70 (K=17) | S1: Tedarikçi 71 (K=18) | T1: Tedarikçi 73 (K=19) | U1: Tedarikçi 75 (K=20) | V1: Tedarikçi 78 (K=21) | W1: Tedarikçi 85 (K=22) | X1: Tedarikçi 89 (K=23) | Y1: Tedarikçi 97 (K=24) | Z1: Tedarikçi 100 (K=25)
A2: Tedarikçi 1 (K=1) | B2: 1 | C2: 0 | D2: 0 | E2: 0 | F2: 0 | G2: 0 | H2: 0 | I2: 0 | J2: 0 | K2: 0 | L2: 0 | M2: 0 | N2: 0 | O2: 0 | P2: 0 | Q2: 0 | R2: 0 | S2: 0 | T2: 0 | U2: 0 | V2: 0 | W2: 0 | X2: 0 | Y2: 0 | Z2: 0
A3: Tedarikçi 2 | B3: 1 | C3: 0 | D3: 0 | E3: 0 | F3: 1 | G3: 0 | H3: 0 | I3: 0 | J3: 0 | K3: 0 | L3: 0 | M3: 0 | N3: 0 | O3: 0 | P3: 0 | Q3: 0 | R3: 0 | S3: 0 | T3: 0 | U3: 0 | V3: 0 | W3: 0 | X3: 0 | Y3: 0 | Z3: 0
A4: Tedarikçi 3 | B4: 0 | C4: 0 | D4: 0 | E4: 0 | F4: 0 | G4: 0 | H4: 0 | I4: 0 | J4: 1 | K4: 0 | L4: 0 | M4: 1 | N4: 0 | O4: 0 | P4: 0 | Q4: 0 | R4: 0 | S4: 0 | T4: 0 | U4: 0 | V4: 0 | W4: 0 | X4: 0 | Y4: 0 | Z4: 0
A5: Tedarikçi 4 | B5: 0 | C5: 0 | D5: 0 | E5: 0 | F5: 0 | G5: 1 | H5: 0 | I5: 0 | J5: 0 | K5: 1 | L5: 0 | M5: 0 | N5: 0 | O5: 0 | P5: 0 | Q5: 0 | R5: 0 | S5: 0 | T5: 0 | U5: 0 | V5: 0 | W5: 0 | X5: 0 | Y5: 0 | Z5: 0
A6: Tedarikçi 5 | B6: 0 | C6: 0 | D6: 0 | E6: 0 | F6: 0 | G6: 0 | H6: 0 | I6: 0 | J6: 0 | K6: 1 | L6: 1 | M6: 0 | N6: 0 | O6: 0 | P6: 0 | Q6: 0 | R6: 0 | S6: 0 | T6: 0 | U6: 0 | V6: 0 | W6: 0 | X6: 0 | Y6: 0 | Z6: 0
A7: Tedarikçi 6 | B7: 0 | C7: 0 | D7: 0 | E7: 0 | F7: 0 | G7: 0 | H7: 0 | I7: 0 | J7: 1 | K7: 0 | L7: 0 | M7: 1 | N7: 0 | O7: 0 | P7: 0 | Q7: 0 | R7: 0 | S7: 0 | T7: 0 | U7: 0 | V7: 0 | W7: 0 | X7: 0 | Y7: 0 | Z7: 0
A8: Tedarikçi 7 (K=2) | B8: 0 | C8: 1 | D8: 0 | E8: 0 | F8: 0 | G8: 0 | H8: 0 | I8: 0 | J8: 0 | K8: 0 | L8: 0 | M8: 0 | N8: 0 | O8: 0 | P8: 0 | Q8: 0 | R8: 0 | S8: 0 | T8: 0 | U8: 0 | V8: 0 | W8: 0 | X8: 0 | Y8: 0 | Z8: 0
A9: Tedarikçi 8 | B9: 0 | C9: 0 | D9: 0 | E9: 0 | F9: 0 | G9: 0 | H9: 0 | I9: 0 | J9: 0 | K9: 1 | L9: 1 | M9: 0 | N9: 0 | O9: 0 | P9: 0 | Q9: 0 | R9: 0 | S9: 0 | T9: 0 | U9: 0 | V9: 0 | W9: 0 | X9: 0 | Y9: 0 | Z9: 0
A10: Tedarikçi 9 | B10: 0 | C10: 0 | D10: 0 | E10: 0 | F10: 0 | G10: 0 | H10: 1 | I10: 0 | J10: 0 | K10: 0 | L10: 1 | M10: 0 | N10: 0 | O10: 0 | P10: 0 | Q10: 0 | R10: 0 | S10: 0 | T10: 0 | U10: 0 | V10: 0 | W10: 0 | X10: 0 | Y10: 0 | Z10: 0
A11: Tedarikçi 10 (K=3) | B11: 0 | C11: 0 | D11: 1 | E11: 0 | F11: 0 | G11: 0 | H11: 0 | I11: 0 | J11: 0 | K11: 0 | L11: 0 | M11: 0 | N11: 0 | O11: 0 | P11: 0 | Q11: 0 | R11: 0 | S11: 0 | T11: 0 | U11: 0 | V11: 0 | W11: 0 | X11: 0 | Y11: 0 | Z11: 0
A12: Tedarikçi 11 | B12: 0 | C12: 0 | D12: 0 | E12: 0 | F12: 0 | G12: 1 | H12: 0 | I12: 0 | J12: 0 | K12: 1 | L12: 0 | M12: 0 | N12: 0 | O12: 0 | P12: 0 | Q12: 0 | R12: 0 | S12: 0 | T12: 0 | U12: 0 | V12: 0 | W12: 0 | X12: 0 | Y12: 0 | Z12: 0
A13: Tedarikçi 12 | B13: 0 | C13: 0 | D13: 0 | E13: 0 | F13: 0 | G13: 0 | H13: 0 | I13: 0 | J13: 1 | K13: 0 | L13: 0 | M13: 1 | N13: 0 | O13: 0 | P13: 0 | Q13: 0 | R13: 0 | S13: 0 | T13: 0 | U13: 0 | V13: 0 | W13: 0 | X13: 0 | Y13: 0 | Z13: 0
... A101: Tedarikçi 100 (K=25) | B101: 0 | C101: 0 | D101: 0 | E101: 0 | F101: 0 | G101: 0 | H101: 0 | I101: 0 | J101: 0 | K101: 0 | L101: 0 | M101: 0 | N101: 0 | O101: 0 | P101: 0 | Q101: 0 | R101: 0 | S101: 0 | T101: 0 | U101: 0 | V101: 0 | W101: 0 | X101: 0 | Y101: 0 | Z101: 1

Sheet gama
A1: f | B1: b | C1: k | D1: Buradaki tüm hesaplamalar mesafe maliyetleri/245 ile yapılmıştır. Çünkü birim kasa maliyeti göz önüne alınmıştır | F1: tedarikçinin araca mesafesi | G1: aracın aktarma merkezine mesafesi
A2: 1 | B2: 1 | C2: 1 | D2: 0.050173747 | F2: =INDEX(Sheet4!$B$2:$CW$26, MATCH(gama!C2,Sheet4!$A$2:$A$26, 0), MATCH(gama!A2, Sheet4!$B$1:$CW$1, 0)) -> 0 | G2: =INDEX(Sheet6!$B$3:$D$27, MATCH(gama!C2,Sheet6!$A$3:$A$27, 0),MATCH(gama!B2, Sheet6!$B$2:$D$2, 0)) -> 0.050173747 | H2: =SUM(F2:G2) -> 0.050173747 | L2: 0.050173747
A3: 1 | B3: 1 | C3: 2 | D3: 0.063115215 | F3: =INDEX(Sheet4!$B$2:$CW$26, MATCH(gama!C3,Sheet4!$A$2:$A$26, 0), MATCH(gama!A3, Sheet4!$B$1:$CW$1, 0)) -> 2.1973878 | G3: =INDEX(Sheet6!$B$3:$D$27, MATCH(gama!C3,Sheet6!$A$3:$A$27, 0),MATCH(gama!B3, Sheet6!$B$2:$D$2, 0)) -> 0.054146285 | H3: =SUM(F3:G3) -> 2.2515341 | L3: 2.2515341
A4: 1 | B4: 1 | C4: 3 | D4: 0.055305066 | F4: =INDEX(Sheet4!$B$2:$CW$26, MATCH(gama!C4,Sheet4!$A$2:$A$26, 0), MATCH(gama!A4, Sheet4!$B$1:$CW$1, 0)) -> 1.5131147 | G4: =INDEX(Sheet6!$B$3:$D$27, MATCH(gama!C4,Sheet6!$A$3:$A$27, 0),MATCH(gama!B4, Sheet6!$B$2:$D$2, 0)) -> 0.049129087 | H4: =SUM(F4:G4) -> 1.5622438 | L4: 1.5622438
A5: 1 | B5: 1 | C5: 4 | D5: 0.063073778 | F5: =INDEX(Sheet4!$B$2:$CW$26, MATCH(gama!C5,Sheet4!$A$2:$A$26, 0), MATCH(gama!A5, Sheet4!$B$1:$CW$1, 0)) -> 1.9762701 | G5: =INDEX(Sheet6!$B$3:$D$27, MATCH(gama!C5,Sheet6!$A$3:$A$27, 0),MATCH(gama!B5, Sheet6!$B$2:$D$2, 0)) -> 0.05500737 | H5: =SUM(F5:G5) -> 2.0312774 | L5: 2.0312774
A6: 1 | B6: 1 | C6: 5 | D6: 0.054444049 | F6: =INDEX(Sheet4!$B$2:$CW$26, MATCH(gama!C6,Sheet4!$A$2:$A$26, 0), MATCH(gama!A6, Sheet4!$B$1:$CW$1, 0)) -> 0.57073681 | G6: =INDEX(Sheet6!$B$3:$D$27, MATCH(gama!C6,Sheet6!$A$3:$A$27, 0),MATCH(gama!B6, Sheet6!$B$2:$D$2, 0)) -> 0.052114511 | H6: =SUM(F6:G6) -> 0.62285132 | L6: 0.62285132
A7: 1 | B7: 1 | C7: 6 | D7: 0.055324915 | F7: =INDEX(Sheet4!$B$2:$CW$26, MATCH(gama!C7,Sheet4!$A$2:$A$26, 0), MATCH(gama!A7, Sheet4!$B$1:$CW$1, 0)) -> 1.1672222 | G7: =INDEX(Sheet6!$B$3:$D$27, MATCH(gama!C7,Sheet6!$A$3:$A$27, 0),MATCH(gama!B7, Sheet6!$B$2:$D$2, 0)) -> 0.050560742 | H7: =SUM(F7:G7) -> 1.217783 | L7: 1.217783
A8: 1 | B8: 1 | C8: 7 | D8: 0.063075108 | F8: =INDEX(Sheet4!$B$2:$CW$26, MATCH(gama!C8,Sheet4!$A$2:$A$26, 0), MATCH(gama!A8, Sheet4!$B$1:$CW$1, 0)) -> 2.1537829 | G8: =INDEX(Sheet6!$B$3:$D$27, MATCH(gama!C8,Sheet6!$A$3:$A$27, 0),MATCH(gama!B8, Sheet6!$B$2:$D$2, 0)) -> 0.054284158 | H8: =SUM(F8:G8) -> 2.208067 | L8: 2.208067
A9: 1 | B9: 1 | C9: 8 | D9: 0.052854164 | F9: =INDEX(Sheet4!$B$2:$CW$26, MATCH(gama!C9,Sheet4!$A$2:$A$26, 0), MATCH(gama!A9, Sheet4!$B$1:$CW$1, 0)) -> 1.3271673 | G9: =INDEX(Sheet6!$B$3:$D$27, MATCH(gama!C9,Sheet6!$A$3:$A$27, 0),MATCH(gama!B9, Sheet6!$B$2:$D$2, 0)) -> 0.047437154 | H9: =SUM(F9:G9) -> 1.3746045 | L9: 1.3746045
A10: 1 | B10: 1 | C10: 9 | D10: 0.061527952 | F10: =INDEX(Sheet4!$B$2:$CW$26, MATCH(gama!C10,Sheet4!$A$2:$A$26, 0), MATCH(gama!A10, Sheet4!$B$1:$CW$1, 0)) -> 1.6592683 | G10: =INDEX(Sheet6!$B$3:$D$27, MATCH(gama!C10,Sheet6!$A$3:$A$27, 0),MATCH(gama!B10, Sheet6!$B$2:$D$2, 0)) -> 0.054755428 | H10: =SUM(F10:G10) -> 1.7140238 | L10: 1.7140238
A11: 1 | B11: 1 | C11: 10 | D11: 0.057588468 | F11: =INDEX(Sheet4!$B$2:$CW$26, MATCH(gama!C11,Sheet4!$A$2:$A$26, 0), MATCH(gama!A11, Sheet4!$B$1:$CW$1, 0)) -> 1.4238003 | G11: =INDEX(Sheet6!$B$3:$D$27, MATCH(gama!C11,Sheet6!$A$3:$A$27, 0),MATCH(gama!B11, Sheet6!$B$2:$D$2, 0)) -> 0.051777038 | H11: =SUM(F11:G11) -> 1.4755773 | L11: 1.4755773
A12: 1 | B12: 1 | C12: 11 | D12: 0.061569191 | F12: =INDEX(Sheet4!$B$2:$CW$26, MATCH(gama!C12,Sheet4!$A$2:$A$26, 0), MATCH(gama!A12, Sheet4!$B$1:$CW$1, 0)) -> 2.0828673 | G12: =INDEX(Sheet6!$B$3:$D$27, MATCH(gama!C12,Sheet6!$A$3:$A$27, 0),MATCH(gama!B12, Sheet6!$B$2:$D$2, 0)) -> 0.053067692 | H12: =SUM(F12:G12) -> 2.135935 | L12: 2.135935
A13: 1 | B13: 1 | C13: 12 | D13: 0.059493324 | F13: =INDEX(Sheet4!$B$2:$CW$26, MATCH(gama!C13,Sheet4!$A$2:$A$26, 0), MATCH(gama!A13, Sheet4!$B$1:$CW$1, 0)) -> 1.2975196 | G13: =INDEX(Sheet6!$B$3:$D$27, MATCH(gama!C13,Sheet6!$A$3:$A$27, 0),MATCH(gama!B13, Sheet6!$B$2:$D$2, 0)) -> 0.054197326 | H13: =SUM(F13:G13) -> 1.3517169 | L13: 1.3517169
... A7501: 100 | B7501: 3 | C7501: 25 | D7501: 0.036469162 | F7501: =INDEX(Sheet4!$B$2:$CW$26, MATCH(gama!C7501,Sheet4!$A$2:$A$26, 0), MATCH(gama!A7501, Sheet4!$B$1:$CW$1, 0)) -> 0 | G7501: =INDEX(Sheet6!$B$3:$D$27, MATCH(gama!C7501,Sheet6!$A$3:$A$27, 0),MATCH(gama!B7501, Sheet6!$B$2:$D$2, 0)) -> 0.036469162 | H7501: =SUM(F7501:G7501) -> 0.036469162 | L7501: 0.036469162

Sheet availability
A1: k | B1: s | C1: t | D1: değer
A2: 1 | B2: 1 | C2: 1 | D2: 1
A3: 1 | B3: 1 | C3: 2 | D3: 1
A4: 1 | B4: 1 | C4: 3 | D4: 1
A5: 1 | B5: 1 | C5: 4 | D5: 1
A6: 1 | B6: 1 | C6: 5 | D6: 1
A7: 1 | B7: 1 | C7: 6 | D7: 1
A8: 1 | B8: 2 | C8: 1 | D8: 1
A9: 1 | B9: 2 | C9: 2 | D9: 1
A10: 1 | B10: 2 | C10: 3 | D10: 1
A11: 1 | B11: 2 | C11: 4 | D11: 1
A12: 1 | B12: 2 | C12: 5 | D12: 1
A13: 1 | B13: 2 | C13: 6 | D13: 1
... A451: 25 | B451: 3 | C451: 6 | D451: 0

Sheet Sheet4
A1: Ad | B1: 1 | C1: 2 | D1: 3 | E1: 4 | F1: 5 | G1: 6 | H1: 7 | I1: 8 | J1: 9 | K1: 10 | L1: 11 | M1: 12 | N1: 13 | O1: 14 | P1: 15 | Q1: 16 | R1: 17 | S1: 18 | T1: 19 | U1: 20 | V1: 21 | W1: 22 | X1: 23 | Y1: 24 | Z1: 25 | AA1: 26 | AB1: 27 | AC1: 28 | AD1: 29 | AE1: 30 | AF1: 31 | AG1: 32 | AH1: 33 | AI1: 34 | AJ1: 35 | AK1: 36 | AL1: 37 | AM1: 38 | AN1: 39 | AO1: 40 | AP1: 41 | AQ1: 42 | AR1: 43 | AS1: 44 | AT1: 45 | AU1: 46 | AV1: 47 | AW1: 48 | AX1: 49 | AY1: 50 | AZ1: 51 | BA1: 52 | BB1: 53 | BC1: 54 | BD1: 55 | BE1: 56 | BF1: 57 | BG1: 58 | BH1: 59 | BI1: 60 | BJ1: 61 | BK1: 62 | BL1: 63 | BM1: 64 | BN1: 65 | BO1: 66 | BP1: 67 | BQ1: 68 | BR1: 69 | BS1: 70 | BT1: 71 | BU1: 72 | BV1: 73 | BW1: 74 | BX1: 75 | BY1: 76 | BZ1: 77 | CA1: 78 | CB1: 79 | CC1: 80 | CD1: 81 | CE1: 82 | CF1: 83 | CG1: 84 | CH1: 85 | CI1: 86 | CJ1: 87 | CK1: 88 | CL1: 89 | CM1: 90 | CN1: 91 | CO1: 92 | CP1: 93 | CQ1: 94 | CR1: 95 | CS1: 96 | CT1: 97 | CU1: 98 | CV1: 99 | CW1: 100
A2: 1 | B2: 0 | C2: 0.55168164 | D2: 1.3687169 | E2: 1.022398 | F2: 1.8827435 | G2: 1.6711689 | H2: 2.1973878 | I2: 1.8449667 | J2: 1.8899751 | K2: 1.5131147 | L2: 1.5110059 | M2: 1.1434824 | N2: 1.2572833 | O2: 1.0178134 | P2: 0.67144545 | Q2: 1.9762701 | R2: 1.5365455 | S2: 0.57073681 | T2: 1.7365506 | U2: 1.3212318 | V2: 1.7164508 | W2: 0.9629578 | X2: 1.1672222 | Y2: 1.1737174 | Z2: 2.1537829 | AA2: 1.2749586 | AB2: 1.3271673 | AC2: 1.1627068 | AD2: 0.87812427 | AE2: 1.9071101 | AF2: 1.6507784 | AG2: 1.9619533 | AH2: 1.6592683 | AI2: 0.90504835 | AJ2: 0.25938093 | AK2: 0.64809288 | AL2: 1.7906544 | AM2: 1.4238003 | AN2: 2.0828673 | AO2: 1.2975196 | AP2: 10.779382 | AQ2: 11.776955 | AR2: 10.940866 | AS2: 11.164048 | AT2: 11.266999 | AU2: 11.667814 | AV2: 10.991588 | AW2: 11.173147 | AX2: 10.320031 | AY2: 10.124695 | AZ2: 10.531451 | BA2: 10.890487 | BB2: 11.105041 | BC2: 10.793187 | BD2: 9.5015594 | BE2: 10.834632 | BF2: 11.711985 | BG2: 10.318802 | BH2: 10.615679 | BI2: 10.4253 | BJ2: 10.71264 | BK2: 11.661788 | BL2: 11.452641 | BM2: 10.761527 | BN2: 9.6969881 | BO2: 10.238888 | BP2: 9.0666531 | BQ2: 9.5980315 | BR2: 9.7302747 | BS2: 9.6508783 | BT2: 10.140936 | BU2: 10.608314 | BV2: 9.3328919 | BW2: 7.868609 | BX2: 8.4129558 | BY2: 9.3851153 | BZ2: 7.9197012 | CA2: 7.8876588 | CB2: 8.8711637 | CC2: 9.0522391 | CD2: 9.7625948 | CE2: 8.635479 | CF2: 9.1494092 | CG2: 9.7759428 | CH2: 10.01241 | CI2: 8.6624392 | CJ2: 8.5795003 | CK2: 8.9697807 | CL2: 8.6533671 | CM2: 9.3374673 | CN2: 8.1662614 | CO2: 8.8402946 | CP2: 8.4106697 | CQ2: 9.3550782 | CR2: 8.57149 | CS2: 9.7128247 | CT2: 9.7128247 | CU2: 8.864716 | CV2: 8.2641284 | CW2: 10.249062
A3: 2 | B3: 2.1973878 | C3: 1.6492129 | D3: 0.99830675 | E3: 1.1755102 | F3: 0.4615219 | G3: 0.90813422 | H3: 0 | I3: 0.4353606 | J3: 0.3487868 | K3: 1.2930308 | L3: 0.69121352 | M3: 1.2793852 | N3: 1.2360376 | O3: 1.1884122 | P3: 2.0937455 | Q3: 0.47018692 | R3: 1.1944476 | S3: 1.7528769 | T3: 0.64438569 | U3: 0.92580453 | V3: 0.65892149 | W3: 1.7698826 | X3: 1.1685086 | Y3: 1.3473602 | Z3: 0.079191641 | AA3: 1.116739 | AB3: 1.7973807 | AC3: 1.1303397 | AD3: 1.8681545 | AE3: 0.45974157 | AF3: 0.64742791 | AG3: 0.52759718 | AH3: 0.80410256 | AI3: 1.5999517 | AJ3: 2.0719733 | AK3: 1.7186476 | AL3: 0.63459947 | AM3: 0.82118173 | AN3: 0.26439024 | AO3: 1.1726728 | AP3: 12.333668 | AQ3: 13.325754 | AR3: 12.556778 | AS3: 12.801891 | AT3: 12.881864 | AU3: 13.322839 | AV3: 12.647149 | AW3: 12.708323 | AX3: 12.101358 | AY3: 11.781635 | AZ3: 12.343006 | BA3: 12.558742 | BB3: 12.791808 | BC3: 12.520923 | BD3: 11.23749 | BE3: 12.50175 | BF3: 13.640748 | BG3: 12.200618 | BH3: 12.463838 | BI3: 12.352521 | BJ3: 12.611846 | BK3: 13.597482 | BL3: 13.32675 | BM3: 12.653253 | BN3: 11.231074 | BO3: 11.826187 | BP3: 10.641218 | BQ3: 11.117352 | BR3: 11.183567 | BS3: 11.080482 | BT3: 11.712969 | BU3: 12.155807 | BV3: 10.991626 | BW3: 9.5709524 | BX3: 10.033978 | BY3: 11.094698 | BZ3: 9.6694932 | CA3: 9.6241884 | CB3: 10.480117 | CC3: 10.682084 | CD3: 11.704973 | CE3: 10.440039 | CF3: 10.97554 | CG3: 11.603271 | CH3: 11.951747 | CI3: 10.593154 | CJ3: 10.402845 | CK3: 10.874738 | CL3: 10.013738 | CM3: 10.923279 | CN3: 9.6956826 | CO3: 10.344261 | CP3: 9.9101216 | CQ3: 10.784251 | CR3: 10.149217 | CS3: 11.252676 | CT3: 11.252676 | CU3: 10.406109 | CV3: 9.9758615 | CW3: 12.095763
A4: 3 | B4: 1.5131147 | C4: 1.0675479 | D4: 1.3032506 | E4: 0.91813368 | F4: 0.83151632 | G4: 1.5326744 | H4: 1.2930308 | I4: 0.86701832 | J4: 0.96306737 | K4: 0 | L4: 0.8449959 | M4: 1.3943493 | N4: 0.30731769 | O4: 0.99269198 | P4: 1.0603443 | Q4: 1.4401851 | R4: 0.098595237 | S4: 1.4121555 | T4: 0.65187337 | U4: 0.64018145 | V4: 0.63984098 | W4: 0.65210165 | X4: 0.49294595 | Y4: 0.34827779 | Z4: 1.3062796 | AA4: 0.40102817 | AB4: 0.52194221 | AC4: 0.55453791 | AD4: 0.77074461 | AE4: 1.3587313 | AF4: 1.2292883 | AG4: 1.4736375 | AH4: 1.4220132 | AI4: 0.61368978 | AJ4: 1.2785099 | AK4: 0.8653165 | AL4: 1.3962632 | AM4: 0.66842689 | AN4: 1.0465926 | AO4: 1.4332711 | AP4: 11.040828 | AQ4: 12.032768 | AR4: 11.265771 | AS4: 11.511961 | AT4: 11.590683 | AU4: 12.033765 | AV4: 11.358476 | AW4: 11.415298 | AX4: 10.828205 | AY4: 10.49363 | AZ4: 11.075119 | BA4: 11.271098 | BB4: 11.505614 | BC4: 11.239392 | BD4: 9.9584836 | BE4: 11.214052 | BF4: 12.401904 | BG4: 10.949685 | BH4: 11.203753 | BI4: 11.115453 | BJ4: 11.365231 | BK4: 12.36112 | BL4: 12.071882 | BM4: 11.404347 | BN4: 9.9381301 | BO4: 10.534273 | BP4: 9.3493199 | BQ4: 9.824328 | BR4: 9.8914636 | BS4: 9.7891542 | BT4: 10.420618 | BU4: 10.862902 | BV4: 9.704413 | BW4: 8.2901204 | BX4: 8.7448277 | BY4: 9.8124961 | BZ4: 8.3952205 | CA4: 8.3479481 | CB4: 9.1898669 | CC4: 9.3929634 | CD4: 10.474775 | CE4: 9.1740613 | CF4: 9.7130422 | CG4: 10.339856 | CH4: 10.71985 | CI4: 9.361608 | CJ4: 9.1409606 | CK4: 9.6336438 | CL4: 8.7251724 | CM4: 9.6316706 | CN4: 8.4029564 | CO4: 9.0512301 | CP4: 8.6170914 | CQ4: 9.4927923 | CR4: 8.857683 | CS4: 9.9597914 | CT4: 9.9597914 | CU4: 9.1134103 | CV4: 8.6955164 | CW4: 10.83593
A5: 4 | B5: 1.9762701 | C5: 1.4577363 | D5: 0.64028072 | E5: 0.98609485 | F5: 0.70758822 | G5: 0.45933248 | H5: 0.47018692 | I5: 0.634398 | J5: 0.54685275 | K5: 1.4401851 | L5: 0.62745908 | M5: 0.92088646 | N5: 1.2823734 | O5: 0.96944756 | P5: 2.0169315 | Q5: 0 | R5: 1.3467449 | S5: 1.4652483 | T5: 0.82694607 | U5: 0.8901699 | V5: 0.83096211 | W5: 1.7641201 | X5: 1.1507576 | Y5: 1.3765989 | Z5: 0.39100163 | AA5: 1.1444773 | AB5: 1.8855461 | AC5: 1.0918631 | AD5: 1.841974 | AE5: 0.084576167 | AF5: 0.32694133 | AG5: 0.057797533 | AH5: 0.37897874 | AI5: 1.5650923 | AJ5: 1.9010555 | AK5: 1.6134892 | AL5: 0.2053839 | AM5: 0.81045894 | AN5: 0.63721409 | AO5: 0.78718595 | AP5: 12.404895 | AQ5: 13.400193 | AR5: 12.610774 | AS5: 12.849806 | AT5: 12.936697 | AU5: 13.366369 | AV5: 12.689502 | AW5: 12.785531 | AX5: 12.102752 | AY5: 11.822094 | AZ5: 12.334352 | BA5: 12.597101 | BB5: 12.824828 | BC5: 12.540599 | BD5: 11.252399 | BE5: 12.540365 | BF5: 13.589149 | BG5: 12.16616 | BH5: 12.442258 | BI5: 12.300347 | BJ5: 12.571141 | BK5: 13.542973 | BL5: 13.296473 | BM5: 12.615507 | BN5: 11.305647 | BO5: 11.887133 | BP5: 10.703172 | BQ5: 11.195687 | BR5: 11.279592 | BS5: 11.182371 | BT5: 11.778022 | BU5: 12.228597 | BV5: 11.029982 | BW5: 9.5926497 | BX5: 10.081141 | BY5: 11.117689 | BZ5: 9.6765613 | CA5: 9.6353681 | CB5: 10.531907 | CC5: 10.728303 | CD5: 11.645852 | CE5: 10.430698 | CF5: 10.959697 | CG5: 11.588009 | CH5: 11.894162 | CI5: 10.537396 | CJ5: 10.386945 | CK5: 10.829604 | CL5: 10.129967 | CM5: 10.982733 | CN5: 9.76745 | CO5: 10.424766 | CP5: 9.990576 | CQ5: 10.885493 | CR5: 10.209011 | CS5: 11.325714 | CT5: 11.325714 | CU5: 10.476659 | CV5: 9.9957108 | CW5: 12.074243
A6: 5 | B6: 0.57073681 | C6: 0.3797493 | D6: 0.83254508 | E6: 0.62253697 | F6: 1.5197928 | G6: 1.1181128 | H6: 1.7528769 | I6: 1.464501 | J6: 1.4867338 | K6: 1.4121555 | L6: 1.1054165 | M6: 0.58230221 | N6: 1.1087652 | O6: 0.58254303 | P6: 0.99545552 | Q6: 1.4652483 | R6: 1.3980423 | S6: 0 | T6: 1.4118221 | U6: 0.99304821 | V6: 1.3933417 | W6: 1.081076 | X6: 0.94873614 | Y6: 1.0719795 | Z6: 1.6980649 | AA6: 1.0624184 | AB6: 1.4331292 | AC6: 0.91073889 | AD6: 1.0537227 | AE6: 1.4045738 | AF6: 1.1498715 | AG6: 1.4429682 | AH6: 1.1213459 | AI6: 0.91789719 | AJ6: 0.63505304 | AK6: 0.70395774 | AL6: 1.2684922 | AM6: 1.0776249 | AN6: 1.6883848 | AO6: 0.73707227 | AP6: 11.331474 | AQ6: 12.329248 | AR6: 11.498698 | AS6: 11.723815 | AT6: 11.824941 | AU6: 12.22916 | AV6: 11.55264 | AW6: 11.723665 | AX6: 10.888401 | AY6: 10.685355 | AZ6: 11.100989 | BA6: 11.452434 | BB6: 11.668397 | BC6: 11.359003 | BD6: 10.067313 | BE6: 11.396467 | BF6: 12.28207 | BG6: 10.889535 | BH6: 11.186112 | BI6: 10.995555 | BJ6: 11.283313 | BK6: 12.231675 | BL6: 12.023369 | BM6: 11.332245 | BN6: 10.24605 | BO6: 10.793684 | BP6: 9.6191402 | BQ6: 10.145429 | BR6: 10.270434 | BS6: 10.188114 | BT6: 10.694214 | BU6: 11.159598 | BV6: 9.8931521 | BW6: 8.4310484 | BX6: 8.9691525 | BY6: 9.9491467 | BZ6: 8.4854027 | CA6: 8.4525027 | CB6: 9.4267302 | CC6: 9.6098549 | CD6: 10.332516 | CE6: 9.2043 | CF6: 9.7191208 | CG6: 10.34581 | CH6: 10.582389 | CI6: 9.2328197 | CJ6: 9.1489876 | CK6: 9.5404798 | CL6: 9.180132 | CM6: 9.8913244 | CN6: 8.7128663 | CO6: 9.3850615 | CP6: 8.9542903 | CQ6: 9.8918385 | CR6: 9.1237245 | CS6: 10.2625 | CT6: 10.2625 | CU6: 9.4135837 | CV6: 8.8275716 | CW6: 10.819436
A7: 6 | B7: 1.1672222 | C7: 0.64686054 | D7: 0.8534389 | E7: 0.42661384 | F7: 0.76348359 | G7: 1.1227411 | H7: 1.1685086 | I7: 0.74984409 | J7: 0.82258217 | K7: 0.49294595 | L7: 0.52641337 | M7: 0.90835504 | N7: 0.19353187 | O7: 0.50154497 | P7: 0.92687056 | Q7: 1.1507576 | R7: 0.45771422 | S7: 0.94873614 | T7: 0.5923832 | U7: 0.26144252 | V7: 0.57227761 | W7: 0.61681456 | X7: 0 | Y7: 0.24125111 | Z7: 1.1512786 | AA7: 0.114685 | AB7: 0.76550489 | AC7: 0.070516255 | AD7: 0.70502551 | AE7: 1.0662808 | AF7: 0.87157643 | AG7: 1.1685846 | AH7: 1.0277604 | AI7: 0.4322157 | AJ7: 0.97681525 | AK7: 0.57597387 | AL7: 1.0491422 | AM7: 0.35462796 | AN7: 0.98572606 | AO7: 0.96186966 | AP7: 11.254147 | AQ7: 12.24949 | AR7: 11.460722 | AS7: 11.700428 | AT7: 11.786589 | AU7: 12.217641 | AV7: 11.540899 | AW7: 11.634937 | AX7: 10.965264 | AY7: 10.67371 | AZ7: 11.201106 | BA7: 11.449162 | BB7: 11.677957 | BC7: 11.397008 | BD7: 10.11002 | BE7: 11.392375 | BF7: 12.480513 | BG7: 11.046304 | BH7: 11.31528 | BI7: 11.191931 | BJ7: 11.455173 | BK7: 12.436365 | BL7: 12.174373 | BM7: 11.49771 | BN7: 10.154994 | BO7: 10.736569 | BP7: 9.5525242 | BQ7: 10.045215 | BR7: 10.131071 | BS7: 10.034935 | BT7: 10.62731 | BU7: 11.077874 | BV7: 9.8818627 | BW7: 8.4479568 | BX7: 8.9316025 | BY7: 9.9729603 | BZ7: 8.5364309 | CA7: 8.4938237 | CB7: 9.3819159 | CC7: 9.5789528 | CD7: 10.542311 | CE7: 9.2973564 | CF7: 9.829529 | CG7: 10.457695 | CH7: 10.789534 | CI7: 9.4312109 | CJ7: 9.2566658 | CK7: 9.716164 | CL7: 8.9863996 | CM7: 9.8322067 | CN7: 8.6167582 | CO7: 9.2744908 | CP7: 8.8403342 | CQ7: 9.7379891 | CR7: 9.0584328 | CS7: 10.175014 | CT7: 10.175014 | CU7: 9.3259228 | CV7: 8.8516157 | CW7: 10.947166
A8: 7 | B8: 2.1537829 | C8: 1.6081623 | D8: 0.93054997 | E8: 1.1314333 | F8: 0.47922502 | G8: 0.8306846 | H8: 0.079191641 | I8: 0.44004647 | J8: 0.34631632 | K8: 1.3062796 | L8: 0.65691709 | M8: 1.2131567 | N8: 1.2305402 | O8: 1.1402119 | P8: 2.0726666 | Q8: 0.39100163 | R8: 1.2077925 | S8: 1.6980649 | T8: 0.65447255 | U8: 0.9020284 | V8: 0.6672192 | W8: 1.7592303 | X8: 1.1512786 | Y8: 1.3399191 | Z8: 0 | AA8: 1.1066568 | AB8: 1.8030587 | AC8: 1.1092012 | AD8: 1.8545408 | AE8: 0.38191394 | AF8: 0.57882604 | AG8: 0.44843455 | AH8: 0.72834786 | AI8: 1.5834926 | AJ8: 2.0357769 | AK8: 1.6914004 | AL8: 0.55747319 | AM8: 0.79937693 | AN8: 0.30842069 | AO8: 1.102709 | AP8: 12.343533 | AQ8: 13.336255 | AR8: 12.563746 | AS8: 12.807854 | AT8: 12.889005 | AU8: 13.328108 | AV8: 12.652157 | AW8: 12.719238 | AX8: 12.099399 | AY8: 11.786233 | AZ8: 12.33938 | BA8: 12.563066 | BB8: 12.795252 | BC8: 12.522089 | BD8: 11.237711 | BE8: 12.506112 | BF8: 13.630028 | BG8: 12.192641 | BH8: 12.458051 | BI8: 12.341588 | BJ8: 12.602862 | BK8: 13.586271 | BL8: 13.319582 | BM8: 12.644769 | BN8: 11.241386 | BO8: 11.834257 | BP8: 10.649315 | BQ8: 11.128289 | BR8: 11.197517 | BS8: 11.095417 | BT8: 11.721723 | BU8: 12.165919 | BV8: 10.995775 | BW8: 9.572079 | BX8: 10.039484 | BY8: 11.096264 | BZ8: 9.6681686 | CA8: 9.6235494 | CB8: 10.486471 | CC8: 10.687522 | CD8: 11.692808 | CE8: 10.43607 | CF8: 10.970549 | CG8: 11.598454 | CH8: 11.939866 | CI8: 10.581415 | CJ8: 10.397767 | CK8: 10.864817 | CL8: 10.030975 | CM8: 10.93099 | CN8: 9.7053059 | CO8: 10.355465 | CP8: 9.9212537 | CQ8: 10.799039 | CR8: 10.15688 | CS8: 11.26273 | CT8: 11.26273 | CU8: 10.415632 | CV8: 9.9767417 | CW8: 12.089948
A9: 8 | B9: 1.3271673 | C9: 1.053385 | D9: 1.6096969 | E9: 1.1383497 | F9: 1.3385235 | G9: 1.8878819 | H9: 1.7973807 | I9: 1.363915 | J9: 1.4567663 | K9: 0.52194221 | L9: 1.2609839 | M9: 1.6152582 | N9: 0.60485557 | O9: 1.2091227 | P9: 0.71585257 | Q9: 1.8855461 | R9: 0.61623119 | S9: 1.4331292 | T9: 1.1531431 | U9: 1.0084453 | V9: 1.1384695 | W9: 0.36944287 | X9: 0.76550489 | Y9: 0.52439614 | Z9: 1.8030587 | AA9: 0.74414787 | AB9: 0 | AC9: 0.8347445 | AD9: 0.45066708 | AE9: 1.8014051 | AF9: 1.6292561 | AG9: 1.9106535 | AH9: 1.7929965 | AI9: 0.51813977 | AJ9: 1.0683036 | AK9: 0.74171417 | AL9: 1.8054899 | AM9: 1.0763692 | AN9: 1.5596744 | AO9: 1.6971407 | AP9: 10.541723 | AQ9: 11.535056 | AR9: 10.760694 | AS9: 11.005038 | AT9: 11.085946 | AU9: 11.525657 | AV9: 10.849881 | AW9: 10.918566 | AX9: 10.310363 | AY9: 9.9842797 | AZ9: 10.55588 | BA9: 10.761364 | BB9: 10.994519 | BC9: 10.725077 | BD9: 9.4428412 | BE9: 10.704375 | BF9: 11.879964 | BG9: 10.428131 | BH9: 10.683123 | BI9: 10.593514 | BJ9: 10.843455 | BK9: 11.839182 | BL9: 11.550675 | BM9: 10.882681 | BN9: 9.4400796 | BO9: 10.031345 | BP9: 8.8464249 | BQ9: 9.3277488 | BR9: 9.4025592 | BS9: 9.3030107 | BT9: 9.9191089 | BU9: 10.364355 | BV9: 9.1942463 | BW9: 7.7753164 | BX9: 8.2368724 | BY9: 9.2985266 | BZ9: 7.8776143 | CA9: 7.8310512 | CB9: 8.6835126 | CC9: 8.8849534 | CD9: 9.9529835 | CE9: 8.6543232 | CF9: 9.1927084 | CG9: 9.8197029 | CH9: 10.198001 | CI9: 8.8397988 | CJ9: 8.6205011 | CK9: 9.1117097 | CL9: 8.2463253 | CM9: 9.1279907 | CN9: 7.903394 | CO9: 8.5553639 | CP9: 8.121094 | CQ9: 9.0063091 | CR9: 8.3538762 | CS9: 9.4611494 | CT9: 9.4611494 | CU9: 8.6135964 | CV9: 8.1804749 | CW9: 10.315252
A10: 9 | B10: 1.6592683 | C10: 1.1746709 | D10: 0.29081382 | E10: 0.74035532 | F10: 0.87013686 | G10: 0.12454421 | H10: 0.80410256 | I10: 0.78797001 | J10: 0.73238452 | K10: 1.4220132 | L10: 0.58448579 | M10: 0.55427456 | N10: 1.1968744 | O10: 0.70071081 | P10: 1.7936085 | Q10: 0.37897874 | R10: 1.3405733 | S10: 1.1213459 | T10: 0.91745038 | U10: 0.79381157 | V10: 0.91289275 | W10: 1.6036054 | X10: 1.0277604 | Y10: 1.2686184 | Z10: 0.72834786 | AA10: 1.0594253 | AB10: 1.7929965 | AC10: 0.95930742 | AD10: 1.6623567 | AE10: 0.35099615 | AF10: 0.21810911 | AG10: 0.34037848 | AH10: 0 | AI10: 1.3928176 | AJ10: 1.6166063 | AK10: 1.3852598 | AL10: 0.17607371 | AM10: 0.75368347 | AN10: 0.89230352 | AO10: 0.41226901 | AP10: 12.231923 | AQ10: 13.228745 | AR10: 12.425219 | AS10: 12.65975 | AT10: 12.75147 | AU10: 13.172837 | AV10: 12.495668 | AW10: 12.616603 | AX10: 11.881543 | AY10: 11.627692 | AZ10: 12.106371 | BA10: 12.400554 | BB10: 12.6244 | BC10: 12.331268 | BD10: 11.040986 | BE10: 12.344043 | BF10: 13.333362 | BG10: 11.921853 | BH10: 12.205874 | BI10: 12.045026 | BJ10: 12.322658 | BK10: 13.285455 | BL10: 13.054003 | BM10: 12.368826 | BN10: 11.136196 | BO10: 11.707196 | BP10: 10.525221 | BQ10: 11.029124 | BR10: 11.126133 | BS10: 11.033466 | BT10: 11.601153 | BU10: 12.056923 | BV10: 10.834905 | BW10: 9.3878004 | BX10: 9.8933859 | BY10: 10.911903 | BZ10: 9.4616729 | CA10: 9.4233035 | CB10: 10.346873 | CC10: 10.539085 | CD10: 11.386816 | CE10: 10.204029 | CF10: 10.728257 | CG10: 11.356364 | CH10: 11.635863 | CI10: 10.281342 | CJ10: 10.156057 | CK10: 10.579781 | CL10: 9.9934225 | CM10: 10.802659 | CN10: 9.5978657 | CO10: 10.260724 | CP10: 9.827078 | CQ10: 10.736442 | CR10: 10.030116 | CS10: 11.155118 | CT10: 11.155118 | CU10: 10.305227 | CV10: 9.7890619 | CW10: 11.838179
A11: 10 | B11: 1.4238003 | C11: 0.87364482 | D11: 0.66366736 | E11: 0.45581774 | F11: 0.4592514 | G11: 0.86579487 | H11: 0.82118173 | I11: 0.42375908 | J11: 0.48214545 | K11: 0.66842689 | L11: 0.1847985 | M11: 0.82466191 | N11: 0.47211484 | O11: 0.50681668 | P11: 1.2735351 | Q11: 0.81045894 | R11: 0.58762542 | S11: 1.0776249 | T11: 0.33433025 | U11: 0.10612157 | V11: 0.31615163 | W11: 0.97015573 | X11: 0.35462796 | Y11: 0.56741233 | Z11: 0.79937693 | AA11: 0.33403589 | AB11: 1.0763692 | AC11: 0.30985111 | AD11: 1.0596321 | AE11: 0.72603456 | AF11: 0.5639319 | AG11: 0.83430994 | AH11: 0.75368347 | AI11: 0.7858709 | AJ11: 1.2693855 | AK11: 0.89922552 | AL11: 0.73572445 | AM11: 0 | AN11: 0.6635003 | AO11: 0.81960771 | AP11: 11.59873 | AQ11: 12.593547 | AR11: 11.8084 | AS11: 12.04907 | AT11: 12.134155 | AU11: 12.566948 | AV11: 11.890337 | AW11: 11.978365 | AX11: 11.318839 | AY11: 11.023363 | AZ11: 11.55522 | BA11: 11.799138 | BB11: 12.028621 | BC11: 11.749125 | BD11: 10.462552 | BE11: 11.742314 | BF11: 12.834786 | BG11: 11.400926 | BH11: 11.669806 | BI11: 11.546171 | BJ11: 11.80973 | BK11: 12.790522 | BL11: 12.528998 | BM11: 11.852307 | BN11: 10.498765 | BO11: 11.083009 | BP11: 9.8986492 | BQ11: 10.388184 | BR11: 10.469989 | BS11: 10.372343 | BT11: 10.972996 | BU11: 11.422129 | BV11: 10.231754 | BW11: 8.7997738 | BX11: 9.2801433 | BY11: 10.324702 | BZ11: 8.8895806 | CA11: 8.8466415 | CB11: 9.7297698 | CC11: 9.9276979 | CD11: 10.896226 | CE11: 9.6514964 | CF11: 10.183911 | CG11: 10.812059 | CH11: 11.143532 | CI11: 9.7852738 | CJ11: 9.6110499 | CK11: 10.070619 | CL11: 9.3195099 | CM11: 10.178813 | CN11: 8.9608369 | CO11: 9.6168483 | CP11: 9.1826101 | CQ11: 10.075489 | CR11: 9.4048818 | CS11: 10.519099 | CT11: 10.519099 | CU11: 9.670376 | CV11: 9.2036403 | CW11: 11.301691
A12: 11 | B12: 2.0828673 | C12: 1.5312569 | D12: 1.0189443 | E12: 1.0785269 | F12: 0.22759395 | G12: 1.0110012 | H12: 0.26439024 | I12: 0.23985545 | J12: 0.20220296 | K12: 1.0465926 | L12: 0.58395983 | M12: 1.2820205 | N12: 1.0236263 | O12: 1.1072118 | P12: 1.9102694 | Q12: 0.63721409 | R12: 0.94851286 | S12: 1.6883848 | T12: 0.4142998 | U12: 0.76907125 | V12: 0.43190523 | W12: 1.5634486 | X12: 0.98572606 | Y12: 1.1377463 | Z12: 0.30842069 | AA12: 0.9169176 | AB12: 1.5596744 | AC12: 0.95918159 | AD12: 1.6677863 | AE12: 0.59430313 | AF12: 0.69390704 | AG12: 0.69331034 | AH12: 0.89230352 | AI12: 1.4087028 | AJ12: 1.9328356 | AK12: 1.5552522 | AL12: 0.74657284 | AM12: 0.6635003 | AN12: 0 | AO12: 1.2016175 | AP12: 12.085452 | AQ12: 13.076756 | AR12: 12.312105 | AS12: 12.558512 | AT12: 12.636953 | AU12: 13.080358 | AV12: 12.40506 | AW12: 12.458882 | AX12: 11.869703 | AY12: 11.540164 | AZ12: 12.114088 | BA12: 12.317596 | BB12: 12.551879 | BC12: 12.284343 | BD12: 11.002462 | BE12: 12.260556 | BF12: 13.424627 | BG12: 11.979421 | BH12: 12.238645 | BI12: 12.136957 | BJ12: 12.392492 | BK12: 13.382332 | BL12: 13.103955 | BM12: 12.432952 | BN12: 10.9824 | BO12: 11.580167 | BP12: 10.395245 | BQ12: 10.86797 | BR12: 10.930948 | BS12: 10.826889 | BT12: 11.466116 | BU12: 11.907313 | BV12: 10.750841 | BW12: 9.3347243 | BX12: 9.7914201 | BY12: 10.857637 | BZ12: 9.4370875 | CA12: 9.3906932 | CB12: 10.236389 | CC12: 10.439556 | CD12: 11.491947 | CE12: 10.211918 | CF12: 10.749113 | CG12: 11.376468 | CH12: 11.738116 | CI12: 10.379436 | CJ12: 10.176646 | CK12: 10.657396 | CL12: 9.7580602 | CM12: 10.677768 | CN12: 9.4479279 | CO12: 10.094626 | CP12: 9.6605995 | CQ12: 10.530817 | CR12: 9.9038307 | CS12: 11.0043 | CT12: 11.0043 | CU12: 10.158417 | CV12: 9.7399574 | CW12: 11.870657
A13: 12 | B13: 1.2975196 | C13: 0.87462953 | D13: 0.18311055 | E13: 0.55905064 | F13: 1.1128583 | G13: 0.38408767 | H13: 1.1726728 | I13: 1.0356224 | J13: 1.0118115 | K13: 1.4332711 | L13: 0.71701105 | M13: 0.15479909 | N13: 1.1538332 | O13: 0.49037308 | P13: 1.5423278 | Q13: 0.78718595 | R13: 1.3716611 | S13: 0.73707227 | T13: 1.0934168 | U13: 0.80523172 | V13: 1.0819115 | W13: 1.4376041 | X13: 0.96186966 | Y13: 1.1914508 | Z13: 1.102709 | AA13: 1.0343477 | AB13: 1.6971407 | AC13: 0.89255637 | AD13: 1.4699928 | AE13: 0.74643264 | AF13: 0.52553909 | AG13: 0.75200426 | AH13: 0.41226901 | AI13: 1.225924 | AJ13: 1.2954767 | AK13: 1.1469058 | AL13: 0.58180206 | AM13: 0.81960771 | AN13: 1.2016175 | AO13: 0 | AP13: 11.982536 | AQ13: 12.980183 | AR13: 12.163289 | AS13: 12.39326 | AT13: 12.489648 | AU13: 12.902646 | AV13: 12.225598 | AW13: 12.370948 | AX13: 11.585468 | AY13: 11.357667 | AZ13: 11.803737 | BA13: 12.127905 | BB13: 12.347841 | BC13: 12.046292 | BD13: 10.75488 | BE13: 12.071649 | BF13: 13.004367 | BG13: 11.604022 | BH13: 11.89528 | BI13: 11.716993 | BJ13: 12.000768 | BK13: 12.954908 | BL13: 12.737336 | BM13: 12.048577 | BN13: 10.891205 | BO13: 11.45132 | BP13: 10.272351 | BQ13: 10.787112 | BR13: 10.897169 | BS13: 10.809185 | BT13: 11.348394 | BU13: 11.808955 | BV13: 10.564852 | BW13: 9.1095788 | BX13: 9.6314435 | BY13: 10.631343 | BZ13: 9.1735874 | CA13: 9.1380011 | CB13: 10.087157 | CC13: 10.275053 | CD13: 11.055709 | CE13: 9.9039261 | CF13: 10.423217 | CG13: 11.050713 | CH13: 11.305305 | CI13: 9.9535924 | CJ13: 9.8519722 | CK13: 10.257602 | CL13: 9.7828598 | CM13: 10.547418 | CN13: 9.3543676 | CO13: 10.022017 | CP13: 9.5894141 | CQ13: 10.512319 | CR13: 9.7768175 | CS13: 10.908969 | CT13: 10.908969 | CU13: 10.059074 | CV13: 9.508663 | CW13: 11.528083
... A28: 27 | B28: 0.7610304 | C28: 0.22587072 | D28: 0.82318848 | E28: 0.34270787 | F28: 1.1241995 | G28: 1.1392093 | H28: 1.4663409 | I28: 1.090595 | J28: 1.1427422 | K28: 0.85561771 | L28: 0.77538602 | M28: 0.73806497 | N28: 0.55685662 | O28: 0.38371079 | P28: 0.71218471 | Q28: 1.3222099 | R28: 0.84848643 | S28: 0.55906083 | T28: 0.97552425 | U28: 0.56270294 | V28: 0.95543039 | W28: 0.60073876 | X28: 0.42099275 | Y28: 0.51302047 | Z28: 1.4314725 | AA28: 0.53462547 | AB28: 0.91274724 | AC28: 0.40524467 | AD28: 0.62048016 | AE28: 1.2434014 | AF28: 1.0004751 | AG28: 1.3221304 | AH28: 1.0816107 | AI28: 0.39988015 | AJ28: 0.60596088 | AK28: 0.30443635 | AL28: 1.1668908 | AM28: 0.66707624 | AN28: 1.3300356 | AO28: 0.85103027 | AP28: 11.156086 | AQ28: 12.153281 | AR28: 11.345777 | AS28: 11.579418 | AT28: 11.672071 | AU28: 12.09196 | AV28: 11.414784 | AW28: 11.542183 | AX28: 10.801507 | AY28: 10.546779 | AZ28: 11.028018 | BA28: 11.319366 | BB28: 11.542911 | BC28: 11.249765 | BD28: 9.9595849 | BE28: 11.26288 | BF28: 12.26901 | BG28: 10.850204 | BH28: 11.130492 | BI28: 10.980275 | BJ28: 11.253411 | BK28: 12.222381 | BL28: 11.981473 | BM28: 11.298523 | BN28: 10.061895 | BO28: 10.629245 | BP28: 9.448062 | BQ28: 9.9560273 | BR28: 10.05935 | BS28: 9.9693045 | BT28: 10.524132 | BU28: 10.981581 | BV28: 9.7539542 | BW28: 8.3062035 | BX28: 8.8137588 | BY28: 9.8302922 | BZ28: 8.3805255 | CA28: 8.3418987 | CB28: 9.2677945 | CC28: 9.4590825 | CD28: 10.324829 | CE28: 9.1251649 | CF28: 9.6508958 | CG28: 10.279124 | CH28: 10.573313 | CI28: 9.2170173 | CJ28: 9.078459 | CK28: 9.5112317 | CL28: 8.9379098 | CM28: 9.724812 | CN28: 8.5239666 | CO28: 9.1889779 | CP28: 8.7557471 | CQ28: 9.6723351 | CR28: 8.9527691 | CS28: 10.080369 | CT28: 10.080369 | CU28: 9.2303792 | CV28: 8.7074528 | CW28: 10.762638
B30: 0 | C30: 0.55168164 | D30: 1.3687169 | E30: 1.022398 | F30: 1.8827435 | G30: 1.6711689 | H30: 2.1973878 | I30: 1.8449667 | J30: 1.8899751 | K30: 1.5131147 | L30: 1.5110059 | M30: 1.1434824 | N30: 1.2572833 | O30: 1.0178134 | P30: 0.67144545 | Q30: 1.9762701 | R30: 1.5365455 | S30: 0.57073681 | T30: 1.7365506 | U30: 1.3212318 | V30: 1.7164508 | W30: 0.9629578 | X30: 1.1672222 | Y30: 1.1737174 | Z30: 2.1537829 | AA30: 1.2749586 | AB30: 1.3271673 | AC30: 1.1627068 | AD30: 0.87812427 | AE30: 1.9071101 | AF30: 1.6507784 | AG30: 1.9619533 | AH30: 1.6592683 | AI30: 0.90504835 | AJ30: 0.25938093 | AK30: 0.64809288 | AL30: 1.7906544 | AM30: 1.4238003 | AN30: 2.0828673 | AO30: 1.2975196 | AP30: 10.779382 | AQ30: 11.776955 | AR30: 10.940866 | AS30: 11.164048 | AT30: 11.266999 | AU30: 11.667814 | AV30: 10.991588 | AW30: 11.173147 | AX30: 10.320031 | AY30: 10.124695 | AZ30: 10.531451 | BA30: 10.890487 | BB30: 11.105041 | BC30: 10.793187 | BD30: 9.5015594 | BE30: 10.834632 | BF30: 11.711985 | BG30: 10.318802 | BH30: 10.615679 | BI30: 10.4253 | BJ30: 10.71264 | BK30: 11.661788 | BL30: 11.452641 | BM30: 10.761527 | BN30: 9.6969881 | BO30: 10.238888 | BP30: 9.0666531 | BQ30: 9.5980315 | BR30: 9.7302747 | BS30: 9.6508783 | BT30: 10.140936 | BU30: 10.608314 | BV30: 9.3328919 | BW30: 7.868609 | BX30: 8.4129558 | BY30: 9.3851153 | BZ30: 7.9197012 | CA30: 7.8876588 | CB30: 8.8711637 | CC30: 9.0522391 | CD30: 9.7625948 | CE30: 8.635479 | CF30: 9.1494092 | CG30: 9.7759428 | CH30: 10.01241 | CI30: 8.6624392 | CJ30: 8.5795003 | CK30: 8.9697807 | CL30: 8.6533671 | CM30: 9.3374673 | CN30: 8.1662614 | CO30: 8.8402946 | CP30: 8.4106697 | CQ30: 9.3550782 | CR30: 8.57149 | CS30: 9.7128247 | CT30: 9.7128247 | CU30: 8.864716 | CV30: 8.2641284 | CW30: 10.249062
B31: 2.1973878 | C31: 1.6492129 | D31: 0.99830675 | E31: 1.1755102 | F31: 0.4615219 | G31: 0.90813422 | H31: 0 | I31: 0.4353606 | J31: 0.3487868 | K31: 1.2930308 | L31: 0.69121352 | M31: 1.2793852 | N31: 1.2360376 | O31: 1.1884122 | P31: 2.0937455 | Q31: 0.47018692 | R31: 1.1944476 | S31: 1.7528769 | T31: 0.64438569 | U31: 0.92580453 | V31: 0.65892149 | W31: 1.7698826 | X31: 1.1685086 | Y31: 1.3473602 | Z31: 0.079191641 | AA31: 1.116739 | AB31: 1.7973807 | AC31: 1.1303397 | AD31: 1.8681545 | AE31: 0.45974157 | AF31: 0.64742791 | AG31: 0.52759718 | AH31: 0.80410256 | AI31: 1.5999517 | AJ31: 2.0719733 | AK31: 1.7186476 | AL31: 0.63459947 | AM31: 0.82118173 | AN31: 0.26439024 | AO31: 1.1726728 | AP31: 12.333668 | AQ31: 13.325754 | AR31: 12.556778 | AS31: 12.801891 | AT31: 12.881864 | AU31: 13.322839 | AV31: 12.647149 | AW31: 12.708323 | AX31: 12.101358 | AY31: 11.781635 | AZ31: 12.343006 | BA31: 12.558742 | BB31: 12.791808 | BC31: 12.520923 | BD31: 11.23749 | BE31: 12.50175 | BF31: 13.640748 | BG31: 12.200618 | BH31: 12.463838 | BI31: 12.352521 | BJ31: 12.611846 | BK31: 13.597482 | BL31: 13.32675 | BM31: 12.653253 | BN31: 11.231074 | BO31: 11.826187 | BP31: 10.641218 | BQ31: 11.117352 | BR31: 11.183567 | BS31: 11.080482 | BT31: 11.712969 | BU31: 12.155807 | BV31: 10.991626 | BW31: 9.5709524 | BX31: 10.033978 | BY31: 11.094698 | BZ31: 9.6694932 | CA31: 9.6241884 | CB31: 10.480117 | CC31: 10.682084 | CD31: 11.704973 | CE31: 10.440039 | CF31: 10.97554 | CG31: 11.603271 | CH31: 11.951747 | CI31: 10.593154 | CJ31: 10.402845 | CK31: 10.874738 | CL31: 10.013738 | CM31: 10.923279 | CN31: 9.6956826 | CO31: 10.344261 | CP31: 9.9101216 | CQ31: 10.784251 | CR31: 10.149217 | CS31: 11.252676 | CT31: 11.252676 | CU31: 10.406109 | CV31: 9.9758615 | CW31: 12.095763
B32: 1.5131147 | C32: 1.0675479 | D32: 1.3032506 | E32: 0.91813368 | F32: 0.83151632 | G32: 1.5326744 | H32: 1.2930308 | I32: 0.86701832 | J32: 0.96306737 | K32: 0 | L32: 0.8449959 | M32: 1.3943493 | N32: 0.30731769 | O32: 0.99269198 | P32: 1.0603443 | Q32: 1.4401851 | R32: 0.098595237 | S32: 1.4121555 | T32: 0.65187337 | U32: 0.64018145 | V32: 0.63984098 | W32: 0.65210165 | X32: 0.49294595 | Y32: 0.34827779 | Z32: 1.3062796 | AA32: 0.40102817 | AB32: 0.52194221 | AC32: 0.55453791 | AD32: 0.77074461 | AE32: 1.3587313 | AF32: 1.2292883 | AG32: 1.4736375 | AH32: 1.4220132 | AI32: 0.61368978 | AJ32: 1.2785099 | AK32: 0.8653165 | AL32: 1.3962632 | AM32: 0.66842689 | AN32: 1.0465926 | AO32: 1.4332711 | AP32: 11.040828 | AQ32: 12.032768 | AR32: 11.265771 | AS32: 11.511961 | AT32: 11.590683 | AU32: 12.033765 | AV32: 11.358476 | AW32: 11.415298 | AX32: 10.828205 | AY32: 10.49363 | AZ32: 11.075119 | BA32: 11.271098 | BB32: 11.505614 | BC32: 11.239392 | BD32: 9.9584836 | BE32: 11.214052 | BF32: 12.401904 | BG32: 10.949685 | BH32: 11.203753 | BI32: 11.115453 | BJ32: 11.365231 | BK32: 12.36112 | BL32: 12.071882 | BM32: 11.404347 | BN32: 9.9381301 | BO32: 10.534273 | BP32: 9.3493199 | BQ32: 9.824328 | BR32: 9.8914636 | BS32: 9.7891542 | BT32: 10.420618 | BU32: 10.862902 | BV32: 9.704413 | BW32: 8.2901204 | BX32: 8.7448277 | BY32: 9.8124961 | BZ32: 8.3952205 | CA32: 8.3479481 | CB32: 9.1898669 | CC32: 9.3929634 | CD32: 10.474775 | CE32: 9.1740613 | CF32: 9.7130422 | CG32: 10.339856 | CH32: 10.71985 | CI32: 9.361608 | CJ32: 9.1409606 | CK32: 9.6336438 | CL32: 8.7251724 | CM32: 9.6316706 | CN32: 8.4029564 | CO32: 9.0512301 | CP32: 8.6170914 | CQ32: 9.4927923 | CR32: 8.857683 | CS32: 9.9597914 | CT32: 9.9597914 | CU32: 9.1134103 | CV32: 8.6955164 | CW32: 10.83593
B33: 1.9762701 | C33: 1.4577363 | D33: 0.64028072 | E33: 0.98609485 | F33: 0.70758822 | G33: 0.45933248 | H33: 0.47018692 | I33: 0.634398 | J33: 0.54685275 | K33: 1.4401851 | L33: 0.62745908 | M33: 0.92088646 | N33: 1.2823734 | O33: 0.96944756 | P33: 2.0169315 | Q33: 0 | R33: 1.3467449 | S33: 1.4652483 | T33: 0.82694607 | U33: 0.8901699 | V33: 0.83096211 | W33: 1.7641201 | X33: 1.1507576 | Y33: 1.3765989 | Z33: 0.39100163 | AA33: 1.1444773 | AB33: 1.8855461 | AC33: 1.0918631 | AD33: 1.841974 | AE33: 0.084576167 | AF33: 0.32694133 | AG33: 0.057797533 | AH33: 0.37897874 | AI33: 1.5650923 | AJ33: 1.9010555 | AK33: 1.6134892 | AL33: 0.2053839 | AM33: 0.81045894 | AN33: 0.63721409 | AO33: 0.78718595 | AP33: 12.404895 | AQ33: 13.400193 | AR33: 12.610774 | AS33: 12.849806 | AT33: 12.936697 | AU33: 13.366369 | AV33: 12.689502 | AW33: 12.785531 | AX33: 12.102752 | AY33: 11.822094 | AZ33: 12.334352 | BA33: 12.597101 | BB33: 12.824828 | BC33: 12.540599 | BD33: 11.252399 | BE33: 12.540365 | BF33: 13.589149 | BG33: 12.16616 | BH33: 12.442258 | BI33: 12.300347 | BJ33: 12.571141 | BK33: 13.542973 | BL33: 13.296473 | BM33: 12.615507 | BN33: 11.305647 | BO33: 11.887133 | BP33: 10.703172 | BQ33: 11.195687 | BR33: 11.279592 | BS33: 11.182371 | BT33: 11.778022 | BU33: 12.228597 | BV33: 11.029982 | BW33: 9.5926497 | BX33: 10.081141 | BY33: 11.117689 | BZ33: 9.6765613 | CA33: 9.6353681 | CB33: 10.531907 | CC33: 10.728303 | CD33: 11.645852 | CE33: 10.430698 | CF33: 10.959697 | CG33: 11.588009 | CH33: 11.894162 | CI33: 10.537396 | CJ33: 10.386945 | CK33: 10.829604 | CL33: 10.129967 | CM33: 10.982733 | CN33: 9.76745 | CO33: 10.424766 | CP33: 9.990576 | CQ33: 10.885493 | CR33: 10.209011 | CS33: 11.325714 | CT33: 11.325714 | CU33: 10.476659 | CV33: 9.9957108 | CW33: 12.074243
B34: 0.57073681 | C34: 0.3797493 | D34: 0.83254508 | E34: 0.62253697 | F34: 1.5197928 | G34: 1.1181128 | H34: 1.7528769 | I34: 1.464501 | J34: 1.4867338 | K34: 1.4121555 | L34: 1.1054165 | M34: 0.58230221 | N34: 1.1087652 | O34: 0.58254303 | P34: 0.99545552 | Q34: 1.4652483 | R34: 1.3980423 | S34: 0 | T34: 1.4118221 | U34: 0.99304821 | V34: 1.3933417 | W34: 1.081076 | X34: 0.94873614 | Y34: 1.0719795 | Z34: 1.6980649 | AA34: 1.0624184 | AB34: 1.4331292 | AC34: 0.91073889 | AD34: 1.0537227 | AE34: 1.4045738 | AF34: 1.1498715 | AG34: 1.4429682 | AH34: 1.1213459 | AI34: 0.91789719 | AJ34: 0.63505304 | AK34: 0.70395774 | AL34: 1.2684922 | AM34: 1.0776249 | AN34: 1.6883848 | AO34: 0.73707227 | AP34: 11.331474 | AQ34: 12.329248 | AR34: 11.498698 | AS34: 11.723815 | AT34: 11.824941 | AU34: 12.22916 | AV34: 11.55264 | AW34: 11.723665 | AX34: 10.888401 | AY34: 10.685355 | AZ34: 11.100989 | BA34: 11.452434 | BB34: 11.668397 | BC34: 11.359003 | BD34: 10.067313 | BE34: 11.396467 | BF34: 12.28207 | BG34: 10.889535 | BH34: 11.186112 | BI34: 10.995555 | BJ34: 11.283313 | BK34: 12.231675 | BL34: 12.023369 | BM34: 11.332245 | BN34: 10.24605 | BO34: 10.793684 | BP34: 9.6191402 | BQ34: 10.145429 | BR34: 10.270434 | BS34: 10.188114 | BT34: 10.694214 | BU34: 11.159598 | BV34: 9.8931521 | BW34: 8.4310484 | BX34: 8.9691525 | BY34: 9.9491467 | BZ34: 8.4854027 | CA34: 8.4525027 | CB34: 9.4267302 | CC34: 9.6098549 | CD34: 10.332516 | CE34: 9.2043 | CF34: 9.7191208 | CG34: 10.34581 | CH34: 10.582389 | CI34: 9.2328197 | CJ34: 9.1489876 | CK34: 9.5404798 | CL34: 9.180132 | CM34: 9.8913244 | CN34: 8.7128663 | CO34: 9.3850615 | CP34: 8.9542903 | CQ34: 9.8918385 | CR34: 9.1237245 | CS34: 10.2625 | CT34: 10.2625 | CU34: 9.4135837 | CV34: 8.8275716 | CW34: 10.819436
B35: 1.1672222 | C35: 0.64686054 | D35: 0.8534389 | E35: 0.42661384 | F35: 0.76348359 | G35: 1.1227411 | H35: 1.1685086 | I35: 0.74984409 | J35: 0.82258217 | K35: 0.49294595 | L35: 0.52641337 | M35: 0.90835504 | N35: 0.19353187 | O35: 0.50154497 | P35: 0.92687056 | Q35: 1.1507576 | R35: 0.45771422 | S35: 0.94873614 | T35: 0.5923832 | U35: 0.26144252 | V35: 0.57227761 | W35: 0.61681456 | X35: 0 | Y35: 0.24125111 | Z35: 1.1512786 | AA35: 0.114685 | AB35: 0.76550489 | AC35: 0.070516255 | AD35: 0.70502551 | AE35: 1.0662808 | AF35: 0.87157643 | AG35: 1.1685846 | AH35: 1.0277604 | AI35: 0.4322157 | AJ35: 0.97681525 | AK35: 0.57597387 | AL35: 1.0491422 | AM35: 0.35462796 | AN35: 0.98572606 | AO35: 0.96186966 | AP35: 11.254147 | AQ35: 12.24949 | AR35: 11.460722 | AS35: 11.700428 | AT35: 11.786589 | AU35: 12.217641 | AV35: 11.540899 | AW35: 11.634937 | AX35: 10.965264 | AY35: 10.67371 | AZ35: 11.201106 | BA35: 11.449162 | BB35: 11.677957 | BC35: 11.397008 | BD35: 10.11002 | BE35: 11.392375 | BF35: 12.480513 | BG35: 11.046304 | BH35: 11.31528 | BI35: 11.191931 | BJ35: 11.455173 | BK35: 12.436365 | BL35: 12.174373 | BM35: 11.49771 | BN35: 10.154994 | BO35: 10.736569 | BP35: 9.5525242 | BQ35: 10.045215 | BR35: 10.131071 | BS35: 10.034935 | BT35: 10.62731 | BU35: 11.077874 | BV35: 9.8818627 | BW35: 8.4479568 | BX35: 8.9316025 | BY35: 9.9729603 | BZ35: 8.5364309 | CA35: 8.4938237 | CB35: 9.3819159 | CC35: 9.5789528 | CD35: 10.542311 | CE35: 9.2973564 | CF35: 9.829529 | CG35: 10.457695 | CH35: 10.789534 | CI35: 9.4312109 | CJ35: 9.2566658 | CK35: 9.716164 | CL35: 8.9863996 | CM35: 9.8322067 | CN35: 8.6167582 | CO35: 9.2744908 | CP35: 8.8403342 | CQ35: 9.7379891 | CR35: 9.0584328 | CS35: 10.175014 | CT35: 10.175014 | CU35: 9.3259228 | CV35: 8.8516157 | CW35: 10.947166
